Workbook
Name _2: #REF!
Name CAPEXOPEX: [1]Parameter!$E$16:$E$23
Name Category: [2]Picklist!$N$2:$N$9
Name Category_externalPT: [1]PreDefinedValues!$M$63:$N$75
Name CONFIGA: Table2[set1]
Name CONFIGA: [3]!Table2[set1]
Name CONFIGA: [4]!Table2[set1]
Name CONFIGA: [3]!Table2[set1]
Name CONFIGA: #REF!
Name Costperday: [1]PreDefinedValues!$C$61:$D$681
Name Criteria1: #REF!
Name Criteria1: #REF!
Name Criteria1: #REF!
Name Criteria1: #REF!
Name Criteria1: #REF!
Name Criteria10: #REF!
Name Criteria10: #REF!
Name Criteria10: #REF!
Name Criteria10: #REF!
Name Criteria10: #REF!
Name Criteria2: #REF!
Name Criteria2: #REF!
Name Criteria2: #REF!
Name Criteria2: #REF!
Name Criteria2: #REF!
Name Criteria3: #REF!
Name Criteria4: #REF!
Name Criteria5: #REF!
Name Criteria6: #REF!
Name Criteria7: #REF!
Name Criteria8: #REF!
Name Criteria9: #REF!
Name cvcvv: [5]PreDefinedValues!$A$6:$E$54
Name DaysMonth: 30
Name Department: [2]Picklist!$C$2:$C$10
Name Disabled: Table2[set1]
Name Disabled: [3]!Table2[set1]
Name Disabled: [4]!Table2[set1]
Name Disabled: [3]!Table2[set1]
Name Disabled: #REF!
Name Driver: [2]Picklist!$M$2:$M$7
Name EDP: [4]!Table9[HTSet5]
Name EDP: Table9[HTSet5]
Name EDPDisabled: [4]!Table16[EDPDisabled]
Name EDPDisabled: Table16[EDPDisabled]
Name EDPDisabledNA_EDP_is_Enabled: [4]!Table27[EDPDisabledNA_EDP_is_Enabled]
Name EDPDisabledNA_EDP_is_Enabled: Table27[EDPDisabledNA_EDP_is_Enabled]
Name Efficiency: [2]Picklist!$P$2:$P$6
Name Enabled: Table5[Set2]
Name Enabled: [3]!Table5[Set2]
Name Enabled: [4]!Table5[Set2]
Name Enabled: [3]!Table5[Set2]
Name Enabled: #REF!
Name EndDate: 42825
Name fy: [2]Picklist!$B$2:$B$6
Name FYall: [1]Parameter!$E$4:$E$12
Name General_Purpose: [4]!Table7[HTSet3]
Name General_Purpose: Table7[HTSet3]
Name General_PurposeDisabled: [4]!Table13[General_PurposeDisabled]
Name General_PurposeDisabled: Table13[General_PurposeDisabled]

Sheet Read me first

Sheet Version Control
A1: Version | B1: Updates
A2: 1.0.6 | B2: 1) Scenario "B" Removed from "Infra assumptions" TAB. Only One Scenario "A" for assesment now. 2) Updated Scenario "A" in "Infra assumptions" as per revised dimensioning 3) Revised CPU and Memory Limits in "Definitions & Rules" TAB. 4) Corrections in "Capacity and Performance Req." TAB to alig with above changes. 5) Corrections in "cBOM - Site X" TAB to align with above changes.
A3: 1.0.7 | B3: 1) Column 1 added "request Type" 2) Column 2 added Site 3) Column 3 added "Vertical domain owner" 4) Column 4 added "sub domain" 5) Column 5 added "k8 cluster" 6) Column 10 added "Inter Pod AAF/AFF Rules" 7) Column 13 added "Persistant storage flag" 8) Correction in Column 27, 28 9) Changes made accordingly in "Definitions and Rules" Tab 10) limits and color formatting added in CPU and RAM tab(Q,R,S)
A4: 1.0.8 | B4: Vodafone internal version
A5: 1.0.9 | B5: Vodafone internal version
A6: 1.1.0 | B6: Vodafone internal version
A7: 1.1.1 | B7: Vodafone internal version
A8: 1.1.2 | B8: 1) "Infra assumptions" TAB updated 2) "Definations and rules" TAB updated with new definitions 3) HT guidelines added under "Infra assumptions" TAB 4) RM dimesnsioning added under "Infra assumptions" TAB 5) A new TAB called "CNF_Info" added. To be filled by vendor 6) A new TAB called "DataSheet" added.(internal vodafone use) 7) Column G"Priority" added 8) Column K "Telemetry POD" added 9) Column V "PCPU Limit for POD type" added 10) Input to Column T, U, V changed to milicores. 1) Correction in CNF_info tab on Hyperthreading Note 2) additional info in Cbom Tab on CPU limit request headers
A9: 1.1.3 | B9: Revision in throughput guidelines with RMS in "Infra Assumptions" tab
A10: 1.1.4 | B10: Typo correction, no changes in rules or addition of any new data
A11: 3.5 | B11: versioning schema changed to to match the series of cindox tool version, hence the next version after 1.1.4 is 3.15
A12: 3.5.1 | B12: new hardware details added uder "infra assumptions"
A13: 3.6.1 | B13: Hardware_Profile Tab added to give more flexibility to change hardware profiles

Sheet Capacity and Performance Req.
A1: NFV TRS capacity and performance requirements
A2: Requirement Title | B2: Requirement details | C2: Vendor comments
A3: cBOM calculation | B3: For each OpCo and for all relevant CNFs in scope, based on the OpCo-specific traffic model, the vendor shall provide the detailed Bill of Materials for the PODs composing the Application (CNF), i.e. the cBOM, using the following sheets: - the cBOM shall be described in full detail using the templates in "cBOM -YRx" sheets - Infrastructure assumptions in "Infrastructure Assumptions" sheet - "Definitions & Rules" sheet - Please also fill in sheet "Please Complete" as per the instructions contained in that sheet - Please also fill in sheet "Supplier Settings" as per the instructions contained in that sheet cBOM shall be provided for infrastructure Scenarios A/Scenario B in sheet "Infra assumptions", Please note that the cBOMs need to include only the CNFs provided by the vendor, i.e. the CNFs but not the CaaS/VIM. Please assume POD resiliency schemes with full session resiliency in case of single blade/RM failure and the appropriate antiaffinity rules among PODs of the same type. The POD sizing shall be performed based for each OpCo on that OpCo's traffic model. PODs are to be used at the % level of utilization of an active POD's processing resources that is indicated in the deployment models of each CNF for each OpCo (that is contained in the OpCo's FSD document) and the capacity statements that are stated for each OpCo and CNF in sheet "Capacity statements" shall be at that same % level of utilization.
A4: Capacity Statements | B4: For each OpCo and for every POD type composing the CNF, the Vendor shall fill the provided capacity template in sheet “Capacity statements” providing the value of the needed KPIs, based on the OpCo traffic model and at the % level of utilization of an active POD's processing resources that is indicated in the deployment models of each CNF for each OpCo (as described in the OpCo's FSD document). This shall be done for all the capacity parameters that matter for each CNF. For pre-5G network functions, capacity parameters are defined in sheet "Capacity KPIs". For 5G network functions, the Vendor shall provide the capacity parameters that matter for each CNF. Just like cBOMs, capacity statements shall be provided for each of infrastructure Scenarios A in sheet "Infra assumptions" The vendor shall state which further important assumptions have been made in case the OpCos' traffic models are incomplete. The vendor shall explain if the provided capacity statements are based on theoretical calculations, computer supported modelling, lab measurements or live network measurements. Whenever available, the vendor shall provide test reports either from lab measurements like load and performance tests or from any real live network in order to support its capacity statements. The vendor shall list all the assumptions considered in providing the performance statement (e.g. pinning if applicable), moreover it shall be specified any optimization methods adopted
A5: Min and Max CNF instance cBOMs and capacity | B5: The vendor shall provide detailed POD breakdowns i.e. cBOMs for each of the following CNF configuration: Minimum Size Single Instance CNF with template in tab “Minimum size CNF Configuration” Maximum Size Single Instance CNF with template in tab “Maximum size CNF Configuration” In the same sheets the vendor shall also provide the overall capacity figures for the Minimum and Maximum CNF instance, using table "CNF capacity & performance" in the lower part of each sheet, at the same % level of utilization as explained for the requirements above. The capacity parameters that matter for the specific CNFs are defined in sheet "Capacity KPI" for pre-5G network functions and instead shall be proposed by the vendor for 5G network functions. Both cBOMs and capacity figures shall be provided considering the traffic profiles for each OpCo and CNF.

Sheet Definitions & Rules 
A1: Definition/Rule: | B1: Accepted values/guidelines: | C1: Remarks:
A2: VCPU Request / Limit (per Pod Type in milicores) | B2: 0 <=10000 millicores (recommended) (In multiples of 50 millicores) 10000 <=20000/ 22000/24000/26000 (please check infra assumptions tab) (in exception cases with justification) | C2: Oversized pods are highly discouraged, cloud-native apps should generally be created as microservices. CPU requests and limits should be specified at the singular pod level - i.e. per POD TYPE in milicores If a basic application contains 'N' identical pods of a certain type, then CPU values (columns J & K) should be entered for just a single pod corresponding to that pod type, and the number of pod type (column E), or equivalently the number of replicas, should be specified as 'N'. For example, if the basic application is comprised of 6 identical pods with each pod requiring 2000-26000 CPU milicores(please check infra tab to get to correct limit), the CPU request/limit = 2000, and the 'Number of Pod Type per CNF instance' = 6. Pods requiring over 10000 VCPUs milicores are not recommended. However, with proper justification POD sizes uptil 20000 VCPU Milicores can be accepted. Special case: if a Pod Type has an AFF (affinity requirement), whereby multiple replicas of the same pod must reside on the same worker node, then the maximum CPU Request/Limit is lower, and equal to 20 divided by the max number of replicas for that pod type. (E.g. max 2 CPU for a Pod Type with AFF requirement, and replicas = 10).
A3: Memory Request / Limit (per Pod Type) | B3: 0 <= 100 (In GB) (for smaller PODs i.e CPU less than 10000 milicores) 0 <= 200 (In GB) (for bigger PODs i.e CPU less than 20000 milicores) | C3: Oversized pods are highly discouraged, cloud-native apps should generally be created as microservices. Memory requests and limits should be specified at the singular pod level - i.e. per POD TYPE. If a basic application contains 'N' identical pods of a certain type, then Memory values (columns L & M) should be entered for just a single pod corresponding to that pod type, and the number of pod type (column E), or equivalently the number of replicas, should be specified as 'N'. For example, if the basic application is comprised of 6 identical pods with each pod requiring 4 GB of memory, the Memory request/limit = 4, and the 'Number of Pod Type per CNF instance' = 6. Pods requiring over 100 GB of RAM are not Recommended,However, with proper justification POD sizes uptil 200 GB can be accepted. . Special case: if a Pod Type has an AFF (affinity requirement), whereby multiple replicas of the same pod must reside on the same worker node, then the maximum Memory Request/Limit is lower, and equal to 128 divided by the max number of replicas for that pod type. (E.g. max 16GB for a Pod Type with AFF requirement, and replicas = 8).
A4: Site | B4: Site Name | C4: Enter the name of the Site for which the Cbom is submitted, Please note that only one site should be entered in one Cbom. For a different site a different Cbom must be filled
A5: Request Type | B5: Feasibility, Committed | C5: Feasibility. This is for high level cost analysis. The demand can be treated as greenfield and won't be retained and integrated to the NVI estate.( Feasibility is the Default value) Committed. This is for firm demands that will be built. These will be modelled in conjunction with the existing planned/deployed hardware.
A6: K8 cluster | B6: Name of the cluster | C6: Self Explanatory
A7: Node Pool | B7: Name of the Node pool | C7: Self Explanatory
A8: Priority | B8: Defining priority class for the POD | C8: Please refer to the priority table below(line 19-28) to assign the right priorty to the POD. Higher priorty POD will be placed instantiated first and alos placed first by the script.
A9: DaemonSet POD | B9: "yes" if the POD is a DaemonSet POD and needs to be on all the worker nodes "No" I f POD is not a DaemonSet POD | C9: The resources of a DaemonSet POD will be reserved on every WN, since one instance of the Telemetry POD will be required on each WN.
A10: Intra Pod AAF/AFF Rules | B10: Either 'None', 'AFF' or 'AAF' | C10: Currently only simple AFF/AAF relationships between pods of the same pod type are supported by VINO. Complex Operators (e.g. Exists, Does Not Exist, LT & GT) affinity operators are OOS (Out of Scope). Please only insert pod affinity/anti-affinity requirement if absolutely required by the application, as this has a large CPU overhead in large K8s clusters.
A11: Inter Pod AAF/AFF Rules | B11: AFF{CNFA.PodA, CNFA.PodB, CNFB.PodC}= Affinity between CNFA.PodA, CNFA.PodB, CNFB.PodC AAF{CNFC.PodC, CNFC.PodA}=antiaffinity between PodC and PodA of CNF C) | C11: To define affinity rules inbetween different PODs
A12: Enhanced HA Required? (Default = FALSE) | B12: TRUE, FALSE | C12: Relevant for CNFs with strict HA requirements. – in case the components (certain pods/pod-types) of a CNF have strict HA requirements. As the target platform is likely to be a virtualized container platform, enacting simple anti-affinity rules may not guarantee that a group of pods are scheduled onto different underlying physical hosts (even if they may be running on different K8s worker nodes). In case strict high-availability is required for a grouping of pods, please consider changing the value in this column from false to true, this will ensure that the pods are scheduled across different availability zones and/or fault-domains (note: this only applies if anti-affinity is requested for a pod-type). Please note that this may result in increased costs, as individual fault domains (requiring non-shared hardware) will need to be sized up to accomodate the application resource requirements.
... A15: [NTWK] North/South bandwidth requirement for Pod Type [PPS x Packet size] | B15: n/a | C15: North/South bandwidth = the amount of traffic entering or leaving the Pod from outside the datacenter (or another legacy node in the datacenter). East/West bandwidth = the amount of traffic entering or leaving the Pod from another Pod within the datacenter.
A16: [NTWK] East/West bandwidth requirement for Pod Type [PPS x Packet size]
A17: List of Special Requirements | B17: n/a | C17: Example special requirements: Storage: Here shall be added the amount of storage to host the containers template/images. Networking: - E.g. multiple network/eth interfaces per pod - E.g. manually-assigned IP addresses (k8s typically allocates addresses automatically from a pool) - E.g. DPDK/SR-IOV support - E.g. NIC bonding - E.g. non-standard K8s networking protocols (e.g. SCTP, in addition to TCP/UDP) - E.g. dual stack IPv4/IPv6 support (i.e. the ability to configure both IPv4 and IPv6 addresses within the same K8s pod) Compute: - NUMA affinity - CPU pinning - inter-pod affinity and anti-affinity - node affinity - baremetal container/cluster support - GPU acceleration - Huge Page support
A19: Priority Table
A20: name | B20: Priority/value | C20: preemptionPolicy | D20: globalDefault
A21: preemptive-high-priority | B21: 1000000 | C21: PreemptLowerPriority | D21: FALSE
A22: nonPreemptive-high-priority | B22: 950000 | C22: Never | D22: FALSE
A23: preemptive-medium-high-priority | B23: 900000 | C23: PreemptLowerPriority | D23: FALSE
A24: nonPreemptive-medium-high-priority | B24: 850000 | C24: Never | D24: FALSE
A25: preemptive-medium-priority | B25: 800000 | C25: PreemptLowerPriority | D25: FALSE
A26: nonPreemptive-medium-priority | B26: 750000 | C26: Never | D26: FALSE
A27: preemptive-low-priority | B27: 700000 | C27: PreemptLowerPriority | D27: FALSE
A28: nonPreemptive--low-priority | B28: 650000 | C28: Never | D28: FALSE
A29: CPU --kube-reserved=[cpu=500m] | B29: Default reservation for kubelet in our dimensioning tool is 500m, it can be max up to 1 cpu | C29: https://kubernetes.io/docs/tasks/administer-cluster/reserve-compute-resources/
A30: CPU --system-reserved=[cpu=500m] | B30: Default reservation for system in our dimensioning tool is 500m, it can be max up to 1 cpu
A31: Mem --kube-reserved=[memory=1000Mi] | B31: Default reservation for kubelet in our dimensioning tool is 1Gi, it can be max up to 4Gi
A32: Mem --system-reserved=[memory=1000Mi] | B32: Default reservation for system in our dimensioning tool is 1Gi, it can be max up to 4Gi

Sheet Infra assumptions 
A1: CNF Sizing, Capacity and Performance
A2: Requirements in this section have been defined in order to understand supported capacities and performance of the CNF in relation to its sizing and scalability. Furthermore, limitations have to be understood impacting scalability and maximum capacities. The focus is on the HW independent scaling of CNFs. But for benchmarking purposes a HW configuration has been defined in detail in order to get a better understanding what a particular CNF running on a particular HW can deliver in terms of capacity and performance. The assumptions in this tab may be subject to change.

Sheet Please Complete
A1: Vodafone Container BOM (cBOM) Template
A3: Document Info:
A4: Document Version: | B4: 3.6.1
A5: Author: | B5: Vodafone Group (O.U - VINO LCM)
A7: Supplier To Complete:
A8: Supplier Name: | B8: Ericsson
A9: Supplier Contact (Email Address): | B9: sean.rowland@ericsson.com
A10: Date of submission: | B10: 45818
A11: Supplier cBOM Version: | B11: Rev AB
A12: OpCo Site Name: | B12: OM
A14: Supplier Instructions:
A15: 1) Please complete the section labelled 'Supplier To Complete' above, by indicating cBOM version (and date of the file), and providing your contact details. 2) Please provide a copy of this cBOM template PER site (i.e. physical deployment - e.g. datacenter). If multiple sites have the exact same requirements for all years, you only need to complete this template ONCE, and you must inform us that it applies for multiple sites. Please do not submit information applicable to multiple sites within a single template. 3) Mandatory tabs that must be completed are coloured in red below ('Please Complete', 'Supplier Settings', 'cBOM - YR1', 'cBOM - YR2',...'cBOM-YR5'.) However please start by completing the 'Supplier Settings' tab first. 4) Please do not modify any sheet/tab names.
A17: SW Versions Considered in this Revision
A18: SC 1.13
A19: EDA 2.17

Sheet DataSheet
A1: Hyperthreading | C1: set1 | E1: Set2
A2: Enabled | C2: Auto | E2: Auto
A3: Disabled | C3: Config-1 | E3: Config-3-(HT)
C4: Config-2 | E4: Config-4-(HT)
A7: Requirement | C7: HTSet3 | E7: HTSet4 | G7: HTSet5 | I7: HTset6 | K7: HTset7
A8: General_Purpose | C8: Disabled | E8: Disabled | G8: Disabled | I8: Disabled | K8: Disabled
A9: SRIOV | C9: Enabled | I9: Enabled | K9: Enabled
A10: EDP
A11: Others
A14: OP_HT | C14: OP_1 | E14: OP_2
A15: Not Used | C15: Disabled | E15: Disabled
A16: Used | C16: Enabled_POD_level_dimensioning_on_CPU_request
C17: Enabled_WN_Level_2_to_1
C18: Enabled_WN_Level_3_to_1_only_for_non_service_affecting_nodepool
C19: Enabled_WN_Level_4_to_1_only_for_non_service_affecting_nodepool
A22: General_PurposeDisabled | C22: General_PurposeEnabled | E22: SRIOVDisabled | G22: EDPDisabled | I22: Huge_PagesDisabled | K22: Huge_PagesEnabled | M22: OthersDisabled | O22: OthersEnabled
A23: Disabled | C23: Disabled | E23: NA_SRIOV_is_Enabled | G23: NA_EDP_is_Enabled | I23: Disabled | K23: Disabled | M23: Disabled | O23: Disabled
A24: Enabled_POD_level_dimensioning_on_CPU_request | I24: Enabled_POD_level_dimensioning_on_CPU_request | M24: Enabled_POD_level_dimensioning_on_CPU_request
A25: Enabled_WN_Level_2_to_1 | I25: Enabled_WN_Level_2_to_1 | M25: Enabled_WN_Level_2_to_1
A26: Enabled_WN_Level_3_to_1_only_for_non_service_affecting_nodepool | I26: Enabled_WN_Level_3_to_1_only_for_non_service_affecting_nodepool | M26: Enabled_WN_Level_3_to_1_only_for_non_service_affecting_nodepool
A27: Enabled_WN_Level_4_to_1_only_for_non_service_affecting_nodepool | I27: Enabled_WN_Level_4_to_1_only_for_non_service_affecting_nodepool | M27: Enabled_WN_Level_4_to_1_only_for_non_service_affecting_nodepool
C29: Throughput
C30: RMS High_Perf-EDP-NoProbing: 50000,
C31: RMS High_Perf-EDP-Probing: 30000,
C32: RMS High_Perf-NoProbing: 30000,
C33: RMS High_Perf-Probing: 20000,
C34: RMS Standard-EDP-NoProbing : 25000
C35: RMS Standard-EDP-Probing: 15000,
C36: RMS Standard-NoProbing : 15000, | K36: EDPDisabledNA_EDP_is_Enabled
C37: RMS Standard-Probing: 10000,
C38: Synergy Hig_Perf(100GB termination): 20000,
C39: Synergy Standard((100GB termination) : 10000, | K39: SRIOVDisabledNA_SRIOV_is_Enabled
C40: Synergy Hig_Perf(40GB termination): 16000, | W40: OthersDisabledDisabled
C41: Synergy Standard((40GB termination): 8000, | AC41: OthersEnabledNA_HT_is_already_Enabled
C42: C7K High_Perf : 12000,
C43: C7k Standard : 6000
C46: General_PurposeDisabledDisabled | E46: General_PurposeDisabledEnabled_POD_level_dimensioning_on_CPU_request | G46: General_PurposeDisabledEnabled_WN_Level_2_to_1 | I46: General_PurposeDisabledEnabled_WN_Level_3_to_1_only_for_non_service_affecting_nodepool | K46: General_PurposeDisabledEnabled_WN_Level_4_to_1_only_for_non_service_affecting_nodepool | M46: General_PurposeEnabledDisabled | O46: SRIOVDisabledNA_SRIOV_is_Enabled | Q46: EDPDisabledNA_EDP_is_Enabled | S46: Huge_PagesDisabledDisabled | U46: Huge_PagesDisabledEnabled_POD_level_dimensioning_on_CPU_request | W46: Huge_PagesDisabledEnabled_WN_Level_2_to_1 | Y46: Huge_PagesDisabledEnabled_WN_Level_3_to_1_only_for_non_service_affecting_nodepool | AA46: Huge_PagesDisabledEnabled_WN_Level_4_to_1_only_for_non_service_affecting_nodepool | AC46: Huge_PagesEnabledDisabled | AE46: OthersDisabledDisabled | AG46: OthersDisabledEnabled_POD_level_dimensioning_on_CPU_request | AI46: OthersDisabledEnabled_WN_Level_2_to_1 | AK46: OthersDisabledEnabled_WN_Level_3_to_1_only_for_non_service_affecting_nodepool | AM46: OthersDisabledEnabled_WN_Level_4_to_1_only_for_non_service_affecting_nodepool | AO46: OthersEnabledDisabled
C47: Config3-Standard | E47: Config3-Standard | G47: Config7-OverProvisioning | I47: Config7-OverProvisioning | K47: Config7-OverProvisioing | M47: Config5-HT | O47: Config8-SRIOV | Q47: Config1-EDP | S47: Config3-Standard | U47: Config3-Standard | W47: Config3-Standard | Y47: Config7-OverProvisioning | AA47: Config7-OverProvisioning | AC47: Config5-HT | AE47: Config3-Standard | AG47: Config3-Standard | AI47: Config3-Standard | AK47: Config7-OverProvisioning | AM47: Config7-OverProvisioning | AO47: Config5-HT
C48: Config4-Standard | E48: Config4-Standard | G48: Custom-Config1 | I48: Custom-Config1 | K48: Custom-Config1 | M48: Config6-HT | O48: Custom-Config1 | Q48: Config2-EDP | S48: Config4-Standard | U48: Config4-Standard | W48: Config4-Standard | Y48: Custom-Config1 | AA48: Custom-Config1 | AC48: Config6-HT | AE48: Config4-Standard | AG48: Config4-Standard | AI48: Config4-Standard | AK48: Custom-Config1 | AM48: Custom-Config1 | AO48: Config6-HT
C49: Custom-Config1 | E49: Custom-Config1 | G49: Custom-Config2 | I49: Custom-Config2 | K49: Custom-Config2 | M49: Custom-Config1 | O49: Custom-Config2 | Q49: Custom-Config1 | S49: Custom-Config1 | U49: Custom-Config1 | W49: Custom-Config1 | Y49: Custom-Config2 | AA49: Custom-Config2 | AC49: Custom-Config1 | AE49: Custom-Config1 | AG49: Custom-Config1 | AI49: Custom-Config1 | AK49: Custom-Config2 | AM49: Custom-Config2 | AO49: Custom-Config1
...

Sheet Hardware_profile
A1: Hardware | B1: Throughput | C1: Total CPU | D1: Total RAM | E1: Sockets | F1: CPU Reservation | G1: RAM Reservation | H1: Usable CPU | I1: Usable RAM | J1: CPU EDP Reservation
A2: RMS High_Perf-EDP-NoProbing | B2: 50000 | C2: 56 | D2: 576 | E2: 2 | F2: =C2 - H2 -> 12 | G2: =D2 - I2 -> 116 | H2: 44 | I2: 460 | J2: 12
A3: RMS High_Perf-EDP-Probing | B3: 30000 | C3: 56 | D3: 576 | E3: 2 | F3: =C3 - H3 -> 12 | G3: =D3 - I3 -> 116 | H3: 44 | I3: 460 | J3: 12
A4: RMS High_Perf-NoProbing | B4: 30000 | C4: 56 | D4: 576 | E4: 2 | F4: =C4 - H4 -> 8 | G4: =D4 - I4 -> 116 | H4: 48 | I4: 460 | J4: 12
A5: RMS High_Perf-Probing | B5: 20000 | C5: 56 | D5: 576 | E5: 2 | F5: =C5 - H5 -> 8 | G5: =D5 - I5 -> 116 | H5: 48 | I5: 460 | J5: 12
A6: RMS Standard-EDP-NoProbing | B6: 25000 | C6: 56 | D6: 576 | E6: 2 | F6: 12 | G6: =D6 - I6 -> 116 | H6: 48 | I6: 460 | J6: 12
A7: RMS Standard-EDP-Probing | B7: 15000 | C7: 56 | D7: 576 | E7: 2 | F7: 12 | G7: =D7 - I7 -> 116 | H7: 48 | I7: 460 | J7: 12
A8: RMS Standard-NoProbing | B8: 15000 | C8: 56 | D8: 576 | E8: 2 | F8: =C8 - H8 -> 8 | G8: =D8 - I8 -> 116 | H8: 48 | I8: 460 | J8: 12
A9: RMS Standard-Probing | B9: 10000 | C9: 56 | D9: 576 | E9: 2 | F9: =C9 - H9 -> 8 | G9: =D9 - I9 -> 116 | H9: 48 | I9: 460 | J9: 0
A10: Synergy Hig_Perf(100GB termination) | B10: 20000 | C10: 56 | D10: 576 | E10: 2 | F10: =C10 - H10 -> 12 | G10: =D10 - I10 -> 116 | H10: 44 | I10: 460 | J10: 0
A11: Synergy Standard((100GB termination) | B11: 10000 | C11: 56 | D11: 576 | E11: 2 | F11: =C11 - H11 -> 12 | G11: =D11 - I11 -> 116 | H11: 44 | I11: 460 | J11: 0
A12: Synergy Hig_Perf(40GB termination) | B12: 16000 | C12: 56 | D12: 576 | E12: 2 | F12: =C12 - H12 -> 12 | G12: =D12 - I12 -> 116 | H12: 44 | I12: 460 | J12: 0
A13: Synergy Standard((40GB termination) | B13: 8000 | C13: 56 | D13: 576 | E13: 2 | F13: =C13 - H13 -> 12 | G13: =D13 - I13 -> 116 | H13: 44 | I13: 460 | J13: 0
A14: C7K High_Perf | B14: 12000 | C14: 40 | D14: 576 | E14: 2 | F14: =C14 - H14 -> 8 | G14: =D14 - I14 -> 116 | H14: 32 | I14: 460 | J14: 0
A15: C7k Standard | B15: 6000 | C15: 40 | D15: 576 | E15: 2 | F15: =C15 - H15 -> 8 | G15: =D15 - I15 -> 116 | H15: 32 | I15: 460 | J15: 0
A16: Intel Sapphire Rapid EDP high perf(100 GB) | B16: 100000 | C16: 64 | D16: 512 | E16: 2 | F16: =C16 - H16 -> 12 | G16: =D16 - I16 -> 102 | H16: 52 | I16: 410 | J16: 12
A17: intel Sapphire Rapid high Perf(100 GB) | B17: 50000 | C17: 64 | D17: 512 | E17: 2 | F17: =C17 - H17 -> 8 | G17: =D17 - I17 -> 102 | H17: 56 | I17: 410 | J17: 0
A18: Intel Sapphire Rapid low perf(25 GB) | B18: 25000 | C18: 64 | D18: 512 | E18: 2 | F18: =C18 - H18 -> 8 | G18: =D18 - I18 -> 102 | H18: 56 | I18: 410 | J18: 0
A19: AMD EDP High Perf-high RAM(100 GB) | B19: 100000 | C19: 64 | D19: 768 | E19: 2 | F19: =C19 - H19 -> 12 | G19: =D19 - I19 -> 148 | H19: 52 | I19: 620 | J19: 12
... A24: AMD low Perf-low RAM(25 GB) | B24: 25000 | C24: 64 | D24: 384 | E24: 2 | F24: =C24 - H24 -> 8 | G24: =D24 - I24 -> 74 | H24: 56 | I24: 310 | J24: 0
A25: Custom_HW_profile1 | B25: 50000 | C25: 64 | D25: 384 | E25: 1 | F25: 8 | G25: 74 | H25: =C25-F25 -> 56 | I25: =D25-G25 -> 310 | J25: 12
A26: Custom_HW_profile2 | B26: 50000 | C26: 64 | D26: 384 | E26: 1 | F26: 8 | G26: 74 | H26: =C26-F26 -> 56 | I26: =D26-G26 -> 310 | J26: 12
A27: Custom_HW_profile3 | B27: 50000 | C27: 64 | D27: 384 | E27: 1 | F27: 8 | G27: 74 | H27: =C27-F27 -> 56 | I27: =D27-G27 -> 310 | J27: 12

Sheet CNF_info
A1: K8 Cluster Name | B1: Nodepool Name | C1: Comments (This columns will not be processed by cindox) | D1: Nodepool Breakup *(If "Yes" selected, VF may/maynot split the nodepool to achieve best possible hardware utilisation) | E1: Special Requirement.(Any special requiremet will create a separate physical cluster for the nodepool) | F1: Hyperthreading *(Option only available for Control Plane)* | G1: OverProvisioning (To be enabled only for control plane and if HT is disabled) | H1: Worker Node Configuration (Note:To be filled by Vodafone not by vendor) | I1: Hardware (Note:To be filled by Vodafone not by vendor) | J1: cpu kubelet (if empty, defaults to a reservation of 500m, does not accept values over 1) | K1: mem kubelet (if empty assumes 2, cannot be more then 4) | L1: cpu system (if empty, defaults to a reservation of 500m, does not accept values over 1) | M1: mem system (if empty assumes 2, cannot be more then 4) | N1: *Note:Hyperthreading enabled does not mean double the cpu performance, only after discussion and approval with CNF vendor shoud it be enabled. | P1: K8 Cluster Name | Q1: Aggergate image size on k8 cluster(Note: if left empty default 10 GB will be assumed )

Sheet cBOM 
A1: Container BOM Template
A3: VNF Name | R3: Requirements - Y1 (FY 21/22)
A4: Request type | B4: Site | C4: Vertical domian owner | D4: Function Standard Name | E4: K8 cluster | F4: Node Pool | G4: Priority | H4: CNF Name | I4: Pod Type | J4: Description of each POD role | K4: DaemonSet POD | L4: Intra Pod AAF/AFF Rules NOTE : In case of AFF (affinity) rules, the CPU limit should not exceed 20 for the entire group of PODS. | M4: Inter Pod AAF/AFF Rules Note: these are the rules between different PODS | N4: Enhanced HA Required? (Default = false, see Definitions Tab for Guidance) | O4: Pod Type QoS | P4: Persistant storage flag-To identify if two different PODs are using same PV.(only applicable for Read write many or Read only Many) | Q4: Pod HPA (Horizontal Pod Autoscaler) Enabled? | R4: Number of CNF instances per Site | S4: Number of Pods per Pod Type (Inc. maxReplicas if HPA is enabled) | T4: [CPU] VCPU REQUEST for Pod Type (Virtual cpu in Milicores, in multiples of 250) *Value to be used in helm chart | U4: [CPU] VCPU LIMIT for Pod Type (Virtual CPU in Milicores, in multiples of 250) *Value to be used in helm chart | V4: [CPU] PCPU LIMIT for Pod Type (Physical CPU in Milicores, in multiples of 250) | W4: [MEM] MEM REQUEST for Pod Type (Enter value in GB) | X4: [MEM] MEM LIMIT for Pod Type (Enter value in GB) | Y4: [STORE] Non-Persistent Storage for Pod Type (Enter value in GB) | Z4: [STORE] Persistent Volumes Required? | AA4: [STORE] Persistent Volume Access Mode | AB4: [STORE] Persistent Storage for Pod Type (Enter value in GB) | AC4: [STORE] Storage IOPS* for Pod Type | AD4: [STORE] Storage R/W Workload Distribution (%/%) | AE4: [NTWK] North/South bandwidth requirement for Pod Type [PPS x Packet size] (Mbit/s) | AF4: [NTWK] East/West bandwidth requirement for Pod Type [PPS x Packet size] (Mbit/s) | AG4: Any special requirement per POD type? (refere to List of Special Requirements in "Definitions & Rules" tab) | AH4: List Special Requirements if applicable. Examples include: Storage for container Images, NodeSelector, NodeAffinity, Multiple Ethernet Interfaces per Pod, CPU Affinity, etc. See definitions Tab for further examples of special requirements.

Sheet Capacity KPIs
A1: Instructions
A2: Here below you can find a list of pre-5G NW functions object of this evaluation and for each one a list of KPIs for capacity statements
A3: For 5G network functions (e.g. UDM/UDR, 5G Signalling), the Vendor shall provide the capacity parameters that matters for each specific application
A4: Those in bold MUST be included by the vendor in the "Capacity statements" sheets, those not in bold are optional and the vendor is free to either provide them or provide alternative ones or nothing
A5: The vendor shall provide these KPIs at the % level of utilization of an active POD's processing resources that is indicated in the deployment models of each CNF for each OpCo (as described in the OpCo's FSD document)
A6: The vendor shall also state any other limiting KPI that could represent a bottleneck for each CNF/PODs in terms of dimensioning
A8: Network Function | B8: KPIs
A9: EPC | B9: • 2G/3G Attached Users SAU [k] • 4G Attached Users [k] • Total Attached Users[k] • 4G Active Users - SAAU [k] • Tput BH UL+DL[Mbps] Overall • Tput BH UL+DL[Mbps] 2G/3G • Tput BH UL+DL[Mbps] 4G • 2G/3G PDP Context [k] • 4G PDP Context [k] • Total PDP context [k]
A10: PCRF | B10: max number of transactions (1 transaction = 1 message one way + 1 message the opposite way) per second on each of the Gx, Rx, Sy, Sd interfaces; max number of concurrent sessions on each of the Gx, Rx, Sy, Sd interfaces; max number of SPR provisioned subscribers
A11: DRA | B11: Diameter TPS: One Diameter Transaction comprises one Diameter Request message and the appropriate Answer message (in Total 4 messages).
A12: STP/SGW | B12: MSU per second: 1 MSU = 1MSU transiting via the STP/SGW i.e. 1 MSU entering and 1 MSU exiting after routing

Sheet Capacity statements
A1: Instructions
A2: Please replace "parameter X" headings with the correponding KPI defined in the Capacity KPIs TAB for each domain/CNF
A4: POD Type | B4: TPS | C4: MPS | D4: KPI 3 | E4: etc.
A5: Signaling Controller
A6: eric-scp-worker | B6: 2600 | C6: =B6*4 -> 10400
A7: eric-bsf-worker | B7: 5600 | C7: =B7*2 -> 11200
A8: eric-bsf-diameter | B8: 2000 | C8: =B8*4 -> 8000
A9: eric-stm-diameter | B9: 20000 | C9: =B9*4 -> 80000
A10: eric-sc-rlf | B10: 6400 | C10: =B10*4 -> 25600
A11: eric-probe-virtual-tap-broker-vtap2 | B11: 12000 | C11: =B11*4 -> 48000
A12: eric-data-wide-column-database-cd | B12: 3180 | C12: 12720
A15: NOTE: The capacity statement for a POD is intended at the % level of utilization of an active POD's processing resources that is indicated in the deployment models of each CNF for each OpCo (that is contained in the OpCo's FSD document)

Sheet Minimum size CNF config
A1: SC (BSF) Minimum Size CNF instance description
A2: POD Type | B2: Number of PODs per type | C2: Number of vCPU per POD | D2: RAM (GB) per POD | E2: Storage (GB) per POD
A3: eric-cm-mediator | B3: 2 | C3: 2 | D3: 0.5 | E3: 0
A4: eric-cm-mediator-key-init | B4: 1 | C4: 0.25 | D4: 0.075 | E4: 0
A5: eric-cm-mediator-notifier | B5: 1 | C5: 2 | D5: 0.5 | E5: 0
A6: eric-cm-yang-provider | B6: 1 | C6: 2.5 | D6: 6.525 | E6: 0
A7: eric-ctrl-bro | B7: 1 | C7: 2 | D7: 4 | E7: 15
A8: eric-data-coordinator-zk | B8: 3 | C8: 2.25 | D8: 4.05 | E8: 5
A9: eric-data-distributed-coordinator-ed | B9: 3 | C9: 1.25 | D9: 1.05 | E9: 1
A10: eric-data-distributed-coordinator-ed-agent | B10: 1 | C10: 1 | D10: 2 | E10: 0
A11: eric-data-distributed-coordinator-ed-sc | B11: 3 | C11: 1.25 | D11: 1.05 | E11: 1
A12: eric-data-document-database-pg | B12: 2 | C12: 1.25 | D12: 2.75 | E12: 8
A13: eric-data-document-database-pg-bragent | B13: 1 | C13: 2 | D13: 2.5 | E13: 0
A14: eric-data-message-bus-kf | B14: 3 | C14: 3 | D14: 9 | E14: 15
... A51: eric-bsf-worker-vtap1 | B51: 2 | C51: 1 | D51: 1 | E51: 0
A52: Total | C52: =SUMPRODUCT(C3:C51, B3:B51) -> 155.5 | E52: =SUMPRODUCT(E3:E51, B3:B51) -> 646
A55: CNF capacity & performance
A56: BSF HTTP TPS | B56: BSF Diameter TPS
A57: ='Capacity statements'!B7 -> 5600 | B57: ='Capacity statements'!B8 -> 2000 | I57: Please write in this row the max capacity values for the minimum size CNF, for each parameter in the columns
A58: =A57/$C$52 -> 36.012862 | B58: =B57/$C$52 -> 12.861736 | G58: =G57/$C$52 -> 0 | I58: Unitary Figures per vCPU
A59: =A57/$E$52 -> 8.6687307 | B59: =B57/$E$52 -> 3.0959752 | G59: =G57/$E$52 -> 0 | I59: Unitary Figures per Storage Unit
A63: SC (SCP) Minimum Size CNF instance description
A64: POD Type | B64: Number of PODs per type | C64: Number of vCPU per POD | D64: RAM (GB) per POD | E64: Storage (GB) per POD
A65: eric-cm-mediator | B65: 2 | C65: 2 | D65: 0.5 | E65: 0
A66: eric-cm-mediator-key-init | B66: 1 | C66: 0.25 | D66: 0.075 | E66: 0
A67: eric-cm-mediator-notifier | B67: 1 | C67: 2 | D67: 0.5 | E67: 0
A68: eric-cm-yang-provider | B68: 1 | C68: 2.5 | D68: 6.525 | E68: 0
A69: eric-ctrl-bro | B69: 1 | C69: 2 | D69: 4 | E69: 15
A70: eric-data-coordinator-zk | B70: 3 | C70: 2.25 | D70: 4.05 | E70: 5
A71: eric-data-distributed-coordinator-ed | B71: 3 | C71: 1.25 | D71: 1.05 | E71: 1
A72: eric-data-distributed-coordinator-ed-agent | B72: 1 | C72: 1 | D72: 2 | E72: 0
A73: eric-data-distributed-coordinator-ed-sc | B73: 3 | C73: 1.25 | D73: 1.05 | E73: 1
A74: eric-data-document-database-pg | B74: 2 | C74: 1.25 | D74: 2.75 | E74: 8
A75: eric-data-document-database-pg-bragent | B75: 1 | C75: 2 | D75: 2.5 | E75: 0
A76: eric-data-message-bus-kf | B76: 3 | C76: 3 | D76: 9 | E76: 15
... A110: eric-scp-worker-vtap2 | B110: 2 | C110: 1 | D110: 2.5 | E110: 0
A111: Total | C111: =SUMPRODUCT(C65:C110, B65:B110) -> 110 | E111: =SUMPRODUCT(E65:E110, B65:B110) -> 406
A114: CNF capacity & performance
A115: SCP TPS
A116: ='Capacity statements'!B6 -> 2600 | I116: Please write in this row the max capacity values for the minimum size CNF, for each parameter in the columns
...

Sheet Maximum size CNF config
A1: SC(BSF) Maximum Size CNF instance description
A2: POD Type | B2: Number of PODs per type | C2: Number of vCPU per POD | D2: RAM (GB) per POD | E2: Storage (GB) per POD
A3: eric-cm-mediator | B3: 2 | C3: 2 | D3: 0.5 | E3: 0
A4: eric-cm-mediator-key-init | B4: 1 | C4: 0.25 | D4: 0.075 | E4: 0
A5: eric-cm-mediator-notifier | B5: 1 | C5: 2 | D5: 0.5 | E5: 0
A6: eric-cm-yang-provider | B6: 1 | C6: 2.5 | D6: 6.525 | E6: 0
A7: eric-ctrl-bro | B7: 1 | C7: 2 | D7: 4 | E7: 15
A8: eric-data-coordinator-zk | B8: 3 | C8: 2.25 | D8: 4.05 | E8: 5
A9: eric-data-distributed-coordinator-ed | B9: 3 | C9: 1.25 | D9: 1.05 | E9: 1
A10: eric-data-distributed-coordinator-ed-agent | B10: 1 | C10: 1 | D10: 2 | E10: 0
A11: eric-data-distributed-coordinator-ed-sc | B11: 3 | C11: 1.25 | D11: 1.05 | E11: 1
A12: eric-data-document-database-pg | B12: 2 | C12: 1.25 | D12: 2.75 | E12: 8
A13: eric-data-document-database-pg-bragent | B13: 1 | C13: 2 | D13: 2.5 | E13: 0
A14: eric-data-message-bus-kf | B14: 3 | C14: 3 | D14: 9 | E14: 15
... A51: eric-bsf-worker-vtap1 | B51: 50 | C51: 1 | D51: 1 | E51: 0
A52: Total | C52: =SUMPRODUCT(C3:C51,B3:B51) -> 1466.25 | E52: =SUMPRODUCT(E3:E51, B3:B51) -> 6406
A55: CNF capacity & performance
A56: BSF HTTP TPS | B56: BSF Diameter TPS
A57: ='Capacity statements'!B7*49 -> 274400 | B57: ='Capacity statements'!B8*49 -> 98000 | I57: Please write in this row the max capacity values for the maximum size CNF, for each parameter in the columns
A58: =A57/$C$52 -> 187.14408 | B58: =B57/$C$52 -> 66.83717 | C58: =C57/$C$52 -> 0 | D58: =D57/$C$52 -> 0 | E58: =E57/$C$52 -> 0 | F58: =F57/$C$52 -> 0 | G58: =G57/$C$52 -> 0 | I58: Unitary figures per vCPU
A59: =A57/$E$52 -> 42.834842 | B59: =B57/$E$52 -> 15.298158 | C59: =C57/$E$52 -> 0 | D59: =D57/$E$52 -> 0 | E59: =E57/$E$52 -> 0 | F59: =F57/$E$52 -> 0 | G59: =G57/$E$52 -> 0 | I59: Unitary figures per Storage unit (GB)
A63: SC(SCP) Maximum Size CNF instance description
A64: POD Type | B64: Number of PODs per type | C64: Number of vCPU per POD | D64: RAM (GB) per POD | E64: Storage (GB) per POD
A65: eric-cm-mediator | B65: 2 | C65: 2 | D65: 0.5 | E65: 0
A66: eric-cm-mediator-key-init | B66: 1 | C66: 0.25 | D66: 0.075 | E66: 0
A67: eric-cm-mediator-notifier | B67: 1 | C67: 2 | D67: 0.5 | E67: 0
A68: eric-cm-yang-provider | B68: 1 | C68: 2.5 | D68: 6.525 | E68: 0
A69: eric-ctrl-bro | B69: 1 | C69: 2 | D69: 4 | E69: 15
A70: eric-data-coordinator-zk | B70: 3 | C70: 2.25 | D70: 4.05 | E70: 5
A71: eric-data-distributed-coordinator-ed | B71: 3 | C71: 1.25 | D71: 1.05 | E71: 1
A72: eric-data-distributed-coordinator-ed-agent | B72: 1 | C72: 1 | D72: 2 | E72: 0
A73: eric-data-distributed-coordinator-ed-sc | B73: 3 | C73: 1.25 | D73: 1.05 | E73: 1
A74: eric-data-document-database-pg | B74: 2 | C74: 1.25 | D74: 2.75 | E74: 8
A75: eric-data-document-database-pg-bragent | B75: 1 | C75: 2 | D75: 2.5 | E75: 0
A76: eric-data-message-bus-kf | B76: 3 | C76: 3 | D76: 9 | E76: 15
... A110: eric-scp-worker-vtap2 | B110: 50 | C110: 1 | D110: 2.5 | E110: 0
A111: Total | C111: =SUMPRODUCT(C65:C110,B65:B110) -> 648.75 | E111: =SUMPRODUCT(E65:E110, B65:B110) -> 406
A114: CNF capacity & performance
A115: SCP TPS
A116: ='Capacity statements'!B6*49 -> 127400 | I116: Please write in this row the max capacity values for the maximum size CNF, for each parameter in the columns
...
